<?xml version="1.0" ?>
<!-- =================================================================================== -->
<!-- |    This document was autogenerated by xacro from /home/sergey/repos/realsense_explorer_bot/src/realsense_explorer_description/urdf/realsense_explorer.urdf.xacro | -->
<!-- |    EDITING THIS FILE BY HAND IS NOT RECOMMENDED                                 | -->
<!-- =================================================================================== -->
<robot name="realsense_explorer">
  <material name="aluminum">
    <color rgba="0.5 0.5 0.5 1"/>
  </material>
  <material name="plastic">
    <color rgba="0.1 0.1 0.1 1"/>
  </material>
  <link name="base_link"/>
  <!-- camera body, with origin at bottom screw mount -->
  <joint name="camera_joint" type="fixed">
    <origin rpy="0 0 0" xyz="0.08 0 -0.035"/>
    <parent link="base_link"/>
    <child link="camera_bottom_screw_frame"/>
  </joint>
  <link name="camera_bottom_screw_frame"/>
  <joint name="camera_link_joint" type="fixed">
    <origin rpy="0 0 0" xyz="0.010600000000000002 0.0175 0.0125"/>
    <parent link="camera_bottom_screw_frame"/>
    <child link="camera_link"/>
  </joint>
  <link name="camera_link">
    <visual>
      <!-- the mesh origin is at front plate in between the two infrared camera axes -->
      <origin rpy="1.5707963267948966 0 1.5707963267948966" xyz="0.0043 -0.0175 0"/>
      <geometry>
        <mesh filename="package://realsense2_description/meshes/d435.dae"/>
      </geometry>
    </visual>
    <collision>
      <origin rpy="0 0 0" xyz="0 -0.0175 0"/>
      <geometry>
        <box size="0.02505 0.09 0.025"/>
      </geometry>
    </collision>
    <inertial>
      <!-- The following are not reliable values, and should not be used for modeling -->
      <mass value="0.072"/>
      <origin xyz="0 0 0"/>
      <inertia ixx="0.003881243" ixy="0.0" ixz="0.0" iyy="0.000498940" iyz="0.0" izz="0.003879257"/>
    </inertial>
  </link>
  <!-- camera depth joints and links -->
  <joint name="camera_depth_joint" type="fixed">
    <origin rpy="0 0 0" xyz="0 0 0"/>
    <parent link="camera_link"/>
    <child link="camera_depth_frame"/>
  </joint>
  <link name="camera_depth_frame"/>
  <joint name="camera_depth_optical_joint" type="fixed">
    <origin rpy="-1.5707963267948966 0 -1.5707963267948966" xyz="0 0 0"/>
    <parent link="camera_depth_frame"/>
    <child link="camera_depth_optical_frame"/>
  </joint>
  <link name="camera_depth_optical_frame"/>
  <!-- camera left IR joints and links -->
  <joint name="camera_infra1_joint" type="fixed">
    <origin rpy="0 0 0" xyz="0 0.0 0"/>
    <parent link="camera_link"/>
    <child link="camera_infra1_frame"/>
  </joint>
  <link name="camera_infra1_frame"/>
  <joint name="camera_infra1_optical_joint" type="fixed">
    <origin rpy="-1.5707963267948966 0 -1.5707963267948966" xyz="0 0 0"/>
    <parent link="camera_infra1_frame"/>
    <child link="camera_infra1_optical_frame"/>
  </joint>
  <link name="camera_infra1_optical_frame"/>
  <!-- camera right IR joints and links -->
  <joint name="camera_infra2_joint" type="fixed">
    <origin rpy="0 0 0" xyz="0 -0.05 0"/>
    <parent link="camera_link"/>
    <child link="camera_infra2_frame"/>
  </joint>
  <link name="camera_infra2_frame"/>
  <joint name="camera_infra2_optical_joint" type="fixed">
    <origin rpy="-1.5707963267948966 0 -1.5707963267948966" xyz="0 0 0"/>
    <parent link="camera_infra2_frame"/>
    <child link="camera_infra2_optical_frame"/>
  </joint>
  <link name="camera_infra2_optical_frame"/>
  <!-- camera color joints and links -->
  <joint name="camera_color_joint" type="fixed">
    <origin rpy="0 0 0" xyz="0 0.015 0"/>
    <parent link="camera_link"/>
    <child link="camera_color_frame"/>
  </joint>
  <link name="camera_color_frame"/>
  <joint name="camera_color_optical_joint" type="fixed">
    <origin rpy="-1.5707963267948966 0 -1.5707963267948966" xyz="0 0 0"/>
    <parent link="camera_color_frame"/>
    <child link="camera_color_optical_frame"/>
  </joint>
  <link name="camera_color_optical_frame"/>
  <material name="invisible">
    <color rgba="0 0 0 0"/>
  </material>
  <material name="green">
    <color rgba="0 1 0 1"/>
  </material>
  <material name="grey">
    <color rgba="0.9 0.9 0.9 1"/>
  </material>
  <link name="base_footprint"/>
  <link name="robot_base">
    <visual>
      <origin rpy="1.57 0 3.14" xyz="0.15 -0.117 0"/>
      <geometry>
        <mesh filename="package://realsense_explorer_description/meshes/robot_chassis.STL" scale="0.001 0.001 0.001"/>
      </geometry>
      <material name="grey"/>
    </visual>
    <collision>
      <origin rpy="1.57 0 3.14" xyz="0.15 -0.117 0"/>
      <geometry>
        <mesh filename="package://realsense_explorer_description/meshes/robot_chassis.STL" scale="0.001 0.001 0.001"/>
      </geometry>
    </collision>
    <inertial>
      <mass value="1.0"/>
      <origin xyz="0 0 0"/>
      <inertia ixx="0.0167" ixy="0.0" ixz="0.0" iyy="0.0208" iyz="0.0" izz="0.0108"/>
    </inertial>
  </link>
  <joint name="base_joint" type="fixed">
    <origin rpy="0 0 0" xyz="0 0 0"/>
    <parent link="base_footprint"/>
    <child link="robot_base"/>
  </joint>
  <joint name="chasis_to_rbot" type="fixed">
    <parent link="robot_base"/>
    <child link="base_link"/>
    <origin rpy="0 0 0" xyz="0 0 0.125"/>
  </joint>
  <link name="link_right_wheel">
    <collision name="link_right_wheel_visual">
      <origin rpy="0 1.5707 1.57" xyz="0 0 0"/>
      <geometry>
        <cylinder length="0.04" radius="0.055"/>
      </geometry>
    </collision>
    <visual name="link_right_wheel_visual">
      <origin rpy="0 1.5707 1.57" xyz="0 0 0"/>
      <geometry>
        <cylinder length="0.04" radius="0.055"/>
      </geometry>
      <material name="invisible"/>
    </visual>
    <inertial>
      <mass value="0.456"/>
      <origin xyz="0 0 0"/>
      <inertia ixx="0.000766" ixy="0.0" ixz="0.0" iyy="0.000766" iyz="0.0" izz="0.000686"/>
    </inertial>
  </link>
  <joint name="joint_right_wheel" type="continuous">
    <origin rpy="0 0 0" xyz="0 -0.1 0.055"/>
    <child link="link_right_wheel"/>
    <parent link="robot_base"/>
    <axis rpy="0 0 0" xyz="0 1 0"/>
    <limit effort="10000" velocity="1000"/>
    <joint_properties damping="1.0" friction="1.0"/>
  </joint>
  <link name="link_left_wheel">
    <collision name="link_left_wheel_visual">
      <origin rpy="0 1.5707 1.57" xyz="0 0 0"/>
      <geometry>
        <cylinder length="0.04" radius="0.055"/>
      </geometry>
    </collision>
    <visual name="link_left_wheel_visual">
      <origin rpy="0 1.5707 1.57" xyz="0 0 0"/>
      <geometry>
        <cylinder length="0.04" radius="0.055"/>
      </geometry>
      <material name="invisible"/>
    </visual>
    <inertial>
      <mass value="0.456"/>
      <origin xyz="0 0 0"/>
      <inertia ixx="0.000766" ixy="0.0" ixz="0.0" iyy="0.000766" iyz="0.0" izz="0.000686"/>
    </inertial>
  </link>
  <joint name="joint_left_wheel" type="continuous">
    <origin rpy="0 0 0" xyz="0 0.1 0.055"/>
    <child link="link_left_wheel"/>
    <parent link="robot_base"/>
    <axis rpy="0 0 0" xyz="0 1 0"/>
    <limit effort="10000" velocity="1000"/>
    <joint_properties damping="1.0" friction="1.0"/>
  </joint>
  <link name="imu_link">
    <visual>
      <geometry>
        <box size="0.015 0.026 0.001"/>
      </geometry>
      <material name="green"/>
    </visual>
    <inertial>
      <mass value="0.000468"/>
      <origin xyz="0 0 0"/>
      <inertia ixx="1.4e-7" ixy="0.0" ixz="0.0" iyy="4.3e-7" iyz="0.0" izz="6.1e-7"/>
    </inertial>
  </link>
  <joint name="imu_joint" type="fixed">
    <origin rpy="0 0 0" xyz="0.114 0 0.05"/>
    <child link="imu_link"/>
    <parent link="robot_base"/>
  </joint>
  <transmission name="right_wheel_transmission">
    <type>transmission_interface/SimpleTransmission</type>
    <joint name="joint_right_wheel">
      <hardwareInterface>
      hardware_interface/VelocityJointInterface
    </hardwareInterface>
    </joint>
    <actuator name="right_wheel_actuator">
      <mechanicalReduction>1</mechanicalReduction>
      <hardwareInterface>
      VelocityJointInterface
    </hardwareInterface>
    </actuator>
  </transmission>
  <transmission name="left_wheel_transmission">
    <type>transmission_interface/SimpleTransmission</type>
    <joint name="joint_left_wheel">
      <hardwareInterface>
      hardware_interface/VelocityJointInterface
    </hardwareInterface>
    </joint>
    <actuator name="left_wheel_actuator">
      <mechanicalReduction>1</mechanicalReduction>
      <hardwareInterface>
      VelocityJointInterface
    </hardwareInterface>
    </actuator>
  </transmission>
</robot>
