<?xml version="1.0"?>

<robot xmlns:xacro="http://www.ros.org/wiki/xacro" name="realsense_explorer">

  <xacro:include filename="$(find realsense2_description)/urdf/_d435.urdf.xacro" />
   
  <link name="base_link" />

  <xacro:sensor_d435 name="camera" topics_ns="camera" parent="robot_base" publish_pointcloud="true">
    <origin xyz="0.08 0 0.09" rpy="0 0 0" />
  </xacro:sensor_d435>

  <material name="invisible">
    <color rgba="0 0 0 0"/>
  </material>

  <material name="green">
    <color rgba="0 1 0 1"/>
  </material>

  <material name="grey">
    <color rgba="0.9 0.9 0.9 1"/>
  </material>

  <gazebo>
    <plugin name="skid_steer_drive_controller" filename="libgazebo_ros_skid_steer_drive.so">
      <updateRate>100.0</updateRate>
      <robotNamespace>/</robotNamespace>

      <leftFrontJoint>joint_front_left_wheel</leftFrontJoint>
      <rightFrontJoint>joint_front_right_wheel</rightFrontJoint>
      <leftRearJoint>joint_back_left_wheel</leftRearJoint>
      <rightRearJoint>joint_back_right_wheel</rightRearJoint>
      <wheelSeparation>0.2</wheelSeparation>  
      <wheelDiameter>0.2</wheelDiameter>
      <robotBaseFrame>base_footprint</robotBaseFrame>
      <torque>20</torque>
      <maxVelocity>2.0</maxVelocity>
      <maxAcceleration>3.0</maxAcceleration>
      <topicName>cmd_vel</topicName>
      <odometryTopic>odom</odometryTopic>
      <odometryFrame>odom</odometryFrame>
      <broadcastTF>true</broadcastTF>
      <covariance_x>0.0001</covariance_x>
      <covariance_y>0.0001</covariance_y>
      <covariance_yaw>0.01</covariance_yaw>
    </plugin>
  </gazebo>

  <link name="base_footprint"/>


  <link name="robot_base">
    <visual>
      <origin rpy="1.57 0 3.14" xyz="0.15 -0.117 0"/>
      <geometry>
        <mesh scale="0.001 0.001 0.001" filename="package://realsense_explorer_description/meshes/robot_chassis.STL"/>
      </geometry>
      <material name="grey"/>
    </visual>
  
    <collision>
      <origin rpy="1.57 0 3.14" xyz="0.15 -0.117 0"/>
      <geometry>
        <mesh scale="0.001 0.001 0.001" filename="package://realsense_explorer_description/meshes/robot_chassis.STL"/>
      </geometry>
    </collision>
    <inertial>
      <mass value="1.0"/>
      <origin xyz="0 0 0"/>
      <inertia ixx="0.0167" ixy="0.0" ixz="0.0"
           iyy="0.0208" iyz="0.0" izz="0.0108"/>
    </inertial>

  </link>

  <joint name="base_joint" type="fixed">
    <origin rpy="0 0 0" xyz="0 0 0" />
    <parent link="base_footprint"/>
    <child link="base_link" />
  </joint>
  
  <joint name="chasis_to_rbot" type="fixed">
    <parent link="base_link"/>
    <child link="robot_base"/>
    <origin xyz="0 0 0" rpy="0 0 0"/>
  </joint>

  <!-- Front Right Wheel -->
  <link name="link_front_right_wheel">        
        
    <collision name="link_front_right_wheel_visual">      
      <origin rpy="1.5707 0 0" xyz="0 0 0"/>      
      <geometry>        
        <cylinder length="0.02" radius="0.02"/>    
      </geometry>         
    </collision>      
       
    <visual name="link_front_right_wheel_visual">      
      <origin rpy="1.5707 0 0" xyz="0 0 0"/>      
      <geometry>        
        <cylinder length="0.02" radius="0.02"/>    
      </geometry>
      <material name="green"/>         
    </visual>

    <inertial>
      <mass value="0.456"/>
      <origin xyz="0 0 0"/>
      <inertia ixx="6.08e-5" ixy="0.0" ixz="0.0"
           iyy="6.08e-5" iyz="0.0" izz="9.12e-5"/>
    </inertial>       
  </link>

  <joint name="joint_front_right_wheel" type="continuous">    
    <origin rpy="0 0 0" xyz="0.095 -0.08 0.02"/>    
    <child link="link_front_right_wheel" />    
    <parent link="robot_base"/>    
    <axis xyz="0 1 0"/>    
    <limit effort="100" velocity="10"/>    
    <joint_properties damping="1.0" friction="1.0" />  
  </joint>

  <!-- Front Left Wheel -->
  <link name="link_front_left_wheel">        

    <collision name="link_front_right_wheel_visual">      
      <origin rpy="1.5707 0 0" xyz="0 0 0"/>      
      <geometry>        
        <cylinder length="0.02" radius="0.02"/>    
      </geometry>         
    </collision>      

    <visual name="link_front_right_wheel_visual">      
      <origin rpy="1.5707 0 0" xyz="0 0 0"/>      
      <geometry>        
        <cylinder length="0.02" radius="0.02"/>    
      </geometry>       
      <material name="green"/>  
    </visual>  

    <inertial>
      <mass value="0.456"/>
      <origin xyz="0 0 0"/>
      <inertia ixx="6.08e-5" ixy="0.0" ixz="0.0"
           iyy="6.08e-5" iyz="0.0" izz="9.12e-5"/>
    </inertial>   
  </link>

  <joint name="joint_front_left_wheel" type="continuous">    
    <origin rpy="0 0 0" xyz="0.095 0.08 0.02"/>    
    <child link="link_front_left_wheel" />    
    <parent link="robot_base"/>    
    <axis xyz="0 1 0"/>    
    <limit effort="100" velocity="10"/>    
    <joint_properties damping="1.0" friction="1.0" />  
  </joint>

  <!-- Back Left Wheel -->
  <link name="link_back_left_wheel">        

    <collision name="link_back_right_wheel_visual">      
      <origin rpy="1.5707 0 0" xyz="0 0 0"/>      
      <geometry>        
        <cylinder length="0.02" radius="0.02"/>    
      </geometry>         
    </collision>      

    <visual name="link_back_right_wheel_visual">      
      <origin rpy="1.5707 0 0" xyz="0 0 0"/>      
      <geometry>        
        <cylinder length="0.02" radius="0.02"/>    
      </geometry>       
      <material name="green"/>  
    </visual>  

    <inertial>
      <mass value="0.456"/>
      <origin xyz="0 0 0"/>
      <inertia ixx="6.08e-5" ixy="0.0" ixz="0.0"
           iyy="6.08e-5" iyz="0.0" izz="9.12e-5"/>
    </inertial>   
  </link>

  <joint name="joint_back_left_wheel" type="continuous">    
    <origin rpy="0 0 0" xyz="-0.073 0.08 0.02"/>    
    <child link="link_back_left_wheel" />    
    <parent link="robot_base"/>    
    <axis xyz="0 1 0"/>    
    <limit effort="100" velocity="10"/>    
    <joint_properties damping="1.0" friction="1.0" />  
  </joint>

  <!-- Back Right Wheel -->
  <link name="link_back_right_wheel">        
        
    <collision name="link_back_right_wheel_visual">      
      <origin rpy="1.5707 0 0" xyz="0 0 0"/>      
      <geometry>        
        <cylinder length="0.02" radius="0.02"/>    
      </geometry>         
    </collision>      
       
    <visual name="link_back_right_wheel_visual">      
      <origin rpy="1.5707 0 0" xyz="0 0 0"/>      
      <geometry>        
        <cylinder length="0.02" radius="0.02"/>    
      </geometry>
      <material name="green"/>         
    </visual>

    <inertial>
      <mass value="0.456"/>
      <origin xyz="0 0 0"/>
      <inertia ixx="6.08e-5" ixy="0.0" ixz="0.0"
           iyy="6.08e-5" iyz="0.0" izz="9.12e-5"/>
    </inertial>       
  </link>

  <joint name="joint_back_right_wheel" type="continuous">    
    <origin rpy="0 0 0" xyz="-0.073 -0.08 0.02"/>    
    <child link="link_back_right_wheel" />    
    <parent link="robot_base"/>    
    <axis xyz="0 1 0"/>    
    <limit effort="100" velocity="10"/>    
    <joint_properties damping="1.0" friction="1.0" />  
  </joint>

  <!-- IMU Link -->
  <link name="imu_link">
      <visual>
        <geometry>
          <box size="0.015 0.026 0.001"/>
        </geometry>
        <material name="green"/>
      </visual>
      <inertial>
        <mass value="0.000468"/>
        <origin xyz="0 0 0"/>
        <inertia ixx="1.4e-7" ixy="0.0" ixz="0.0"
             iyy="4.3e-7" iyz="0.0" izz="6.1e-7"/>
      </inertial>
  </link>

  <joint name="imu_joint" type="fixed">    
    <origin rpy="0 0 0" xyz="0.114 0 0.05"/>    
    <child link="imu_link" />    
    <parent link="robot_base"/>    
  </joint>
</robot>